<?xml version="1.0" ?>
<!-- =================================================================================== -->
<!-- |    This document was autogenerated by xacro from jeep.urdf.xacro                | -->
<!-- |    EDITING THIS FILE BY HAND IS NOT RECOMMENDED                                 | -->
<!-- =================================================================================== -->
<robot name="jeep">
  <link name="base_footprint"/>
  <link name="base_link">
    <visual>
      <origin rpy="0 0 0" xyz="-0.06 0 0.1"/>
      <geometry>
        <mesh filename="package://jeep_description/meshes/body.dae" scale="1 0.96 1"/>
      </geometry>
    </visual>
    <collision>
      <origin rpy="0 0 0" xyz="-0.06 0 0.1"/>
      <geometry>
        <mesh filename="package://jeep_description/meshes/body_collision.stl" scale="0.96 0.96 0.96"/>
      </geometry>
    </collision>
    <inertial>
      <origin rpy="0 0 0" xyz="-0.25 0 0.3"/>
      <mass value="2242.0"/>
      <inertia ixx="575.9137499999999" ixy="0" ixz="0" iyy="3232.488696" iyz="0" izz="3673.882446"/>
    </inertial>
  </link>
  <link name="hood_logo">
    <visual>
      <origin rpy="0 0 0" xyz="-0.06 0 0.102"/>
      <geometry>
        <mesh filename="package://jeep_description/meshes/hood_logo.dae" scale="1 1 1"/>
      </geometry>
    </visual>
  </link>
  <joint name="base_link_joint" type="fixed">
    <parent link="base_footprint"/>
    <child link="base_link"/>
    <origin rpy="0 0 0" xyz="1.458 0 0.365"/>
  </joint>
  <joint name="hood_logo_joint" type="fixed">
    <parent link="base_link"/>
    <child link="hood_logo"/>
    <origin rpy="0 0 0" xyz="0 0 0"/>
  </joint>
  <link name="wheel_rl">
    <visual>
      <origin rpy="-1.57079632679 0.0 0" xyz="0 0 0"/>
      <geometry>
        <mesh filename="package://jeep_description/meshes/wheel.dae"/>
      </geometry>
    </visual>
    <collision>
      <geometry>
        <cylinder length="0.25" radius="0.365"/>
      </geometry>
    </collision>
    <inertial>
      <origin rpy="0 0 0" xyz="0 0 0"/>
      <mass value="10.0"/>
      <inertia ixx="0.38514583333333335" ixy="0" ixz="0" iyy="0.38514583333333335" iyz="0" izz="0.666125"/>
    </inertial>
  </link>
  <joint name="wheel_rl_joint" type="continuous">
    <parent link="base_link"/>
    <child link="wheel_rl"/>
    <origin rpy="-1.57079632679 0 0" xyz="-1.458 0.825 0"/>
    <axis xyz="0 0 1"/>
    <limit effort="0" velocity="22.0"/>
  </joint>
  <link name="wheel_rr">
    <visual>
      <origin rpy="-1.57079632679 3.1415926535 0" xyz="0 0 0"/>
      <geometry>
        <mesh filename="package://jeep_description/meshes/wheel.dae"/>
      </geometry>
    </visual>
    <collision>
      <geometry>
        <cylinder length="0.25" radius="0.365"/>
      </geometry>
    </collision>
    <inertial>
      <origin rpy="0 0 0" xyz="0 0 0"/>
      <mass value="10.0"/>
      <inertia ixx="0.38514583333333335" ixy="0" ixz="0" iyy="0.38514583333333335" iyz="0" izz="0.666125"/>
    </inertial>
  </link>
  <joint name="wheel_rr_joint" type="continuous">
    <parent link="base_link"/>
    <child link="wheel_rr"/>
    <origin rpy="-1.57079632679 0 0" xyz="-1.458 -0.825 0"/>
    <axis xyz="0 0 1"/>
    <limit effort="0" velocity="22.0"/>
  </joint>
  <link name="wheel_fl">
    <visual>
      <origin rpy="-1.57079632679 0.0 0" xyz="0 0 0"/>
      <geometry>
        <mesh filename="package://jeep_description/meshes/wheel.dae"/>
      </geometry>
    </visual>
    <collision>
      <geometry>
        <cylinder length="0.25" radius="0.365"/>
      </geometry>
    </collision>
    <inertial>
      <origin rpy="0 0 0" xyz="0 0 0"/>
      <mass value="10.0"/>
      <inertia ixx="0.38514583333333335" ixy="0" ixz="0" iyy="0.38514583333333335" iyz="0" izz="0.666125"/>
    </inertial>
  </link>
  <link name="steer_fl">
    <inertial>
      <origin rpy="0 0 0" xyz="-0.013054 -0.0295 0"/>
      <mass value="1.0"/>
      <inertia ixx="0.037227" ixy="0" ixz="0" iyy="0.04" iyz="0" izz="0.06"/>
    </inertial>
  </link>
  <joint name="steer_fl_joint" type="revolute">
    <parent link="base_link"/>
    <child link="steer_fl"/>
    <origin rpy="0 0 0" xyz="1.458 0.825 0"/>
    <axis xyz="0 0 1"/>
    <limit effort="0.0" lower="-0.6" upper="0.6" velocity="0.0"/>
  </joint>
  <joint name="wheel_fl_joint" type="continuous">
    <parent link="steer_fl"/>
    <child link="wheel_fl"/>
    <origin rpy="-1.57079632679 0 0" xyz="0 0 0"/>
    <axis xyz="0 0 1"/>
    <limit effort="0" velocity="22.0"/>
  </joint>
  <link name="wheel_fr">
    <visual>
      <origin rpy="-1.57079632679 3.141592653589793 0" xyz="0 0 0"/>
      <geometry>
        <mesh filename="package://jeep_description/meshes/wheel.dae"/>
      </geometry>
    </visual>
    <collision>
      <geometry>
        <cylinder length="0.25" radius="0.365"/>
      </geometry>
    </collision>
    <inertial>
      <origin rpy="0 0 0" xyz="0 0 0"/>
      <mass value="10.0"/>
      <inertia ixx="0.38514583333333335" ixy="0" ixz="0" iyy="0.38514583333333335" iyz="0" izz="0.666125"/>
    </inertial>
  </link>
  <link name="steer_fr">
    <inertial>
      <origin rpy="0 0 0" xyz="-0.013054 -0.0295 0"/>
      <mass value="1.0"/>
      <inertia ixx="0.037227" ixy="0" ixz="0" iyy="0.04" iyz="0" izz="0.06"/>
    </inertial>
  </link>
  <joint name="steer_fr_joint" type="revolute">
    <parent link="base_link"/>
    <child link="steer_fr"/>
    <origin rpy="0 0 0" xyz="1.458 -0.825 0"/>
    <axis xyz="0 0 1"/>
    <limit effort="0.0" lower="-0.6" upper="0.6" velocity="0.0"/>
  </joint>
  <joint name="wheel_fr_joint" type="continuous">
    <parent link="steer_fr"/>
    <child link="wheel_fr"/>
    <origin rpy="-1.57079632679 0 0" xyz="0 0 0"/>
    <axis xyz="0 0 1"/>
    <limit effort="0" velocity="22.0"/>
  </joint>
  <gazebo reference="hood_logo">
    <visual>
      <transparency>0.01</transparency>
    </visual>
  </gazebo>
</robot>
